Workbook
Name Slicer_Segment: #N/A

Sheet Sheet2
D1: Ship Mode | G1: Alt AM to remove duplicates
A2: Total Sales | B2: =SUM(Data[Sales]) -> 2297200.9 | D2: Second Class | E2: =SUMIFS(Data[Sales],Data[Ship Mode],D2) -> 459193.57
D3: Standard Class | E3: =SUMIFS(Data[Sales],Data[Ship Mode],D3) -> 1358215.7
D4: First Class | E4: =SUMIFS(Data[Sales],Data[Ship Mode],D4) -> 351428.42
D5: Same Day | E5: =SUMIFS(Data[Sales],Data[Ship Mode],D5) -> 128363.12

Sheet Sheet4
A3: Row Labels | B3: Sum of Sales
A4: First Class | B4: 351428.42
A5: Central | B5: 58746.915
A6: East | B6: 113587.05
A7: West | B7: 129761.89
A8: South | B8: 49332.566
A9: Same Day | B9: 128363.13
A10: Central | B10: 20415.41
A11: East | B11: 43326.832
A12: West | B12: 43603.71
A13: South | B13: 21017.173
A14: Second Class | B14: 459193.57
A15: Central | B15: 103550.01
... A24: Grand Total | B24: 2297200.9
A28: Row Labels | B28: Sum of Sales
A29: First Class | B29: 86400.988
A30: Same Day | B30: 22645.443
A31: Second Class | B31: 81568.581
A32: Standard Class | B32: 239038.14
A33: Grand Total | B33: 429653.15

Sheet Sales
A1: Row ID | B1: Order ID | C1: Order Date | D1: Ship Date | E1: Ship Mode | F1: Customer ID | G1: Customer Name | H1: Segment | I1: Country | J1: City | K1: State | L1: Postal Code | M1: Region | N1: Product ID | O1: Category | P1: Sub-Category | Q1: Product Name | R1: Sales | S1: Quantity | T1: Discount | U1: Profit | V1: Returned | W1: Manager
A2: 1 | B2: CA-2016-152156 | C2: 42682 | D2: 42685 | E2: Second Class | F2: CG-12520 | G2: Claire Gute | H2: Consumer | I2: United States | J2: Henderson | K2: Kentucky | L2: 42420 | M2: South | N2: FUR-BO-10001798 | O2: Furniture | P2: Bookcases | Q2: Bush Somerset Collection Bookcase | R2: 261.96 | S2: 2 | T2: 0 | U2: 41.9136 | V2: =IF(ISNA(MATCH(Sales!$B2,Returns!$B$2:$B$297,0)),"No","Yes") -> No | W2: =INDEX(People!$A$2:$A$5,MATCH(Sales!$M2,People!$B$2:$B$5,0)) -> Cassandra Brandow | Z2: We did Index and Match for reverse Lookup
A3: 2 | B3: CA-2016-152156 | C3: 42682 | D3: 42685 | E3: Second Class | F3: CG-12520 | G3: Claire Gute | H3: Consumer | I3: United States | J3: Henderson | K3: Kentucky | L3: 42420 | M3: South | N3: FUR-CH-10000454 | O3: Furniture | P3: Chairs | Q3: Hon Deluxe Fabric Upholstered Stacking Chairs, Rounded Back | R3: 731.94 | S3: 3 | T3: 0 | U3: 219.582 | V3: =IF(ISNA(MATCH(Sales!$B3,Returns!$B$2:$B$297,0)),"No","Yes") -> No | W3: =INDEX(People!$A$2:$A$5,MATCH(Sales!$M3,People!$B$2:$B$5,0)) -> Cassandra Brandow
A4: 3 | B4: CA-2016-138688 | C4: 42533 | D4: 42537 | E4: Second Class | F4: DV-13045 | G4: Darrin Van Huff | H4: Corporate | I4: United States | J4: Los Angeles | K4: California | L4: 90036 | M4: West | N4: OFF-LA-10000240 | O4: Office Supplies | P4: Labels | Q4: Self-Adhesive Address Labels for Typewriters by Universal | R4: 14.62 | S4: 2 | T4: 0 | U4: 6.8714 | V4: =IF(ISNA(MATCH(Sales!$B4,Returns!$B$2:$B$297,0)),"No","Yes") -> No | W4: =INDEX(People!$A$2:$A$5,MATCH(Sales!$M4,People!$B$2:$B$5,0)) -> Anna Andreadi | Z4: We used Isna and If to get Yes and No
A5: 4 | B5: US-2015-108966 | C5: 42288 | D5: 42295 | E5: Standard Class | F5: SO-20335 | G5: Sean O'Donnell | H5: Consumer | I5: United States | J5: Fort Lauderdale | K5: Florida | L5: 33311 | M5: South | N5: FUR-TA-10000577 | O5: Furniture | P5: Tables | Q5: Bretford CR4500 Series Slim Rectangular Table | R5: 957.5775 | S5: 5 | T5: 0.45 | U5: -383.031 | V5: =IF(ISNA(MATCH(Sales!$B5,Returns!$B$2:$B$297,0)),"No","Yes") -> No | W5: =INDEX(People!$A$2:$A$5,MATCH(Sales!$M5,People!$B$2:$B$5,0)) -> Cassandra Brandow
A6: 5 | B6: US-2015-108966 | C6: 42288 | D6: 42295 | E6: Standard Class | F6: SO-20335 | G6: Sean O'Donnell | H6: Consumer | I6: United States | J6: Fort Lauderdale | K6: Florida | L6: 33311 | M6: South | N6: OFF-ST-10000760 | O6: Office Supplies | P6: Storage | Q6: Eldon Fold 'N Roll Cart System | R6: 22.368 | S6: 2 | T6: 0.2 | U6: 2.5164 | V6: =IF(ISNA(MATCH(Sales!$B6,Returns!$B$2:$B$297,0)),"No","Yes") -> No | W6: =INDEX(People!$A$2:$A$5,MATCH(Sales!$M6,People!$B$2:$B$5,0)) -> Cassandra Brandow
A7: 6 | B7: CA-2014-115812 | C7: 41799 | D7: 41804 | E7: Standard Class | F7: BH-11710 | G7: Brosina Hoffman | H7: Consumer | I7: United States | J7: Los Angeles | K7: California | L7: 90032 | M7: West | N7: FUR-FU-10001487 | O7: Furniture | P7: Furnishings | Q7: Eldon Expressions Wood and Plastic Desk Accessories, Cherry Wood | R7: 48.86 | S7: 7 | T7: 0 | U7: 14.1694 | V7: =IF(ISNA(MATCH(Sales!$B7,Returns!$B$2:$B$297,0)),"No","Yes") -> No | W7: =INDEX(People!$A$2:$A$5,MATCH(Sales!$M7,People!$B$2:$B$5,0)) -> Anna Andreadi
A8: 7 | B8: CA-2014-115812 | C8: 41799 | D8: 41804 | E8: Standard Class | F8: BH-11710 | G8: Brosina Hoffman | H8: Consumer | I8: United States | J8: Los Angeles | K8: California | L8: 90032 | M8: West | N8: OFF-AR-10002833 | O8: Office Supplies | P8: Art | Q8: Newell 322 | R8: 7.28 | S8: 4 | T8: 0 | U8: 1.9656 | V8: =IF(ISNA(MATCH(Sales!$B8,Returns!$B$2:$B$297,0)),"No","Yes") -> No | W8: =INDEX(People!$A$2:$A$5,MATCH(Sales!$M8,People!$B$2:$B$5,0)) -> Anna Andreadi
A9: 8 | B9: CA-2014-115812 | C9: 41799 | D9: 41804 | E9: Standard Class | F9: BH-11710 | G9: Brosina Hoffman | H9: Consumer | I9: United States | J9: Los Angeles | K9: California | L9: 90032 | M9: West | N9: TEC-PH-10002275 | O9: Technology | P9: Phones | Q9: Mitel 5320 IP Phone VoIP phone | R9: 907.152 | S9: 6 | T9: 0.2 | U9: 90.7152 | V9: =IF(ISNA(MATCH(Sales!$B9,Returns!$B$2:$B$297,0)),"No","Yes") -> No | W9: =INDEX(People!$A$2:$A$5,MATCH(Sales!$M9,People!$B$2:$B$5,0)) -> Anna Andreadi
A10: 9 | B10: CA-2014-115812 | C10: 41799 | D10: 41804 | E10: Standard Class | F10: BH-11710 | G10: Brosina Hoffman | H10: Consumer | I10: United States | J10: Los Angeles | K10: California | L10: 90032 | M10: West | N10: OFF-BI-10003910 | O10: Office Supplies | P10: Binders | Q10: DXL Angle-View Binders with Locking Rings by Samsill | R10: 18.504 | S10: 3 | T10: 0.2 | U10: 5.7825 | V10: =IF(ISNA(MATCH(Sales!$B10,Returns!$B$2:$B$297,0)),"No","Yes") -> No | W10: =INDEX(People!$A$2:$A$5,MATCH(Sales!$M10,People!$B$2:$B$5,0)) -> Anna Andreadi
A11: 10 | B11: CA-2014-115812 | C11: 41799 | D11: 41804 | E11: Standard Class | F11: BH-11710 | G11: Brosina Hoffman | H11: Consumer | I11: United States | J11: Los Angeles | K11: California | L11: 90032 | M11: West | N11: OFF-AP-10002892 | O11: Office Supplies | P11: Appliances | Q11: Belkin F5C206VTEL 6 Outlet Surge | R11: 114.9 | S11: 5 | T11: 0 | U11: 34.47 | V11: =IF(ISNA(MATCH(Sales!$B11,Returns!$B$2:$B$297,0)),"No","Yes") -> No | W11: =INDEX(People!$A$2:$A$5,MATCH(Sales!$M11,People!$B$2:$B$5,0)) -> Anna Andreadi
A12: 11 | B12: CA-2014-115812 | C12: 41799 | D12: 41804 | E12: Standard Class | F12: BH-11710 | G12: Brosina Hoffman | H12: Consumer | I12: United States | J12: Los Angeles | K12: California | L12: 90032 | M12: West | N12: FUR-TA-10001539 | O12: Furniture | P12: Tables | Q12: Chromcraft Rectangular Conference Tables | R12: 1706.184 | S12: 9 | T12: 0.2 | U12: 85.3092 | V12: =IF(ISNA(MATCH(Sales!$B12,Returns!$B$2:$B$297,0)),"No","Yes") -> No | W12: =INDEX(People!$A$2:$A$5,MATCH(Sales!$M12,People!$B$2:$B$5,0)) -> Anna Andreadi
A13: 12 | B13: CA-2014-115812 | C13: 41799 | D13: 41804 | E13: Standard Class | F13: BH-11710 | G13: Brosina Hoffman | H13: Consumer | I13: United States | J13: Los Angeles | K13: California | L13: 90032 | M13: West | N13: TEC-PH-10002033 | O13: Technology | P13: Phones | Q13: Konftel 250 Conference phone - Charcoal black | R13: 911.424 | S13: 4 | T13: 0.2 | U13: 68.3568 | V13: =IF(ISNA(MATCH(Sales!$B13,Returns!$B$2:$B$297,0)),"No","Yes") -> No | W13: =INDEX(People!$A$2:$A$5,MATCH(Sales!$M13,People!$B$2:$B$5,0)) -> Anna Andreadi
A14: 13 | B14: CA-2017-114412 | C14: 42840 | D14: 42845 | E14: Standard Class | F14: AA-10480 | G14: Andrew Allen | H14: Consumer | I14: United States | J14: Concord | K14: North Carolina | L14: 28027 | M14: South | N14: OFF-PA-10002365 | O14: Office Supplies | P14: Paper | Q14: Xerox 1967 | R14: 15.552 | S14: 3 | T14: 0.2 | U14: 5.4432 | V14: =IF(ISNA(MATCH(Sales!$B14,Returns!$B$2:$B$297,0)),"No","Yes") -> No | W14: =INDEX(People!$A$2:$A$5,MATCH(Sales!$M14,People!$B$2:$B$5,0)) -> Cassandra Brandow
A15: 14 | B15: CA-2016-161389 | C15: 42709 | D15: 42714 | E15: Standard Class | F15: IM-15070 | G15: Irene Maddox | H15: Consumer | I15: United States | J15: Seattle | K15: Washington | L15: 98103 | M15: West | N15: OFF-BI-10003656 | O15: Office Supplies | P15: Binders | Q15: Fellowes PB200 Plastic Comb Binding Machine | R15: 407.976 | S15: 3 | T15: 0.2 | U15: 132.5922 | V15: =IF(ISNA(MATCH(Sales!$B15,Returns!$B$2:$B$297,0)),"No","Yes") -> No | W15: =INDEX(People!$A$2:$A$5,MATCH(Sales!$M15,People!$B$2:$B$5,0)) -> Anna Andreadi
A16: 15 | B16: US-2015-118983 | C16: 42330 | D16: 42334 | E16: Standard Class | F16: HP-14815 | G16: Harold Pawlan | H16: Home Office | I16: United States | J16: Fort Worth | K16: Texas | L16: 76106 | M16: Central | N16: OFF-AP-10002311 | O16: Office Supplies | P16: Appliances | Q16: Holmes Replacement Filter for HEPA Air Cleaner, Very Large Room, HEPA Filter | R16: 68.81 | S16: 5 | T16: 0.8 | U16: -123.858 | V16: =IF(ISNA(MATCH(Sales!$B16,Returns!$B$2:$B$297,0)),"No","Yes") -> No | W16: =INDEX(People!$A$2:$A$5,MATCH(Sales!$M16,People!$B$2:$B$5,0)) -> Kelly Williams
... A2235: 2234 | B2235: CA-2015-123232 | C2235: 42352 | D2235: 42354 | E2235: Second Class | F2235: DJ-13630 | G2235: Doug Jacobs | H2235: Consumer | I2235: United States | J2235: Portland | K2235: Oregon | L2235: 97206 | M2235: West | N2235: TEC-PH-10001051 | O2235: Technology | P2235: Phones | Q2235: HTC One | R2235: 319.968 | S2235: 4 | T2235: 0.2 | U2235: 35.9964 | V2235: =IF(ISNA(MATCH(Sales!$B2235,Returns!$B$2:$B$297,0)),"No","Yes") -> No | W2235: =INDEX(People!$A$2:$A$5,MATCH(Sales!$M2235,People!$B$2:$B$5,0)) -> Anna Andreadi
A2236: 2235 | B2236: CA-2017-104066 | C2236: 43074 | D2236: 43079 | E2236: Standard Class | F2236: QJ-19255 | G2236: Quincy Jones | H2236: Corporate | I2236: United States | J2236: Burlington | K2236: Vermont | L2236: 05408 | M2236: East | N2236: TEC-AC-10001013 | O2236: Technology | P2236: Accessories | Q2236: Logitech ClearChat Comfort/USB Headset H390 | R2236: 205.03 | S2236: 7 | T2236: 0 | U2236: 67.6599 | V2236: =IF(ISNA(MATCH(Sales!$B2236,Returns!$B$2:$B$297,0)),"No","Yes") -> No | W2236: =INDEX(People!$A$2:$A$5,MATCH(Sales!$M2236,People!$B$2:$B$5,0)) -> Chuck Magee
A2237: 2236 | B2237: CA-2015-145849 | C2237: 42262 | D2237: 42264 | E2237: Second Class | F2237: CT-11995 | G2237: Carol Triggs | H2237: Consumer | I2237: United States | J2237: Indianapolis | K2237: Indiana | L2237: 46203 | M2237: Central | N2237: OFF-ST-10000025 | O2237: Office Supplies | P2237: Storage | Q2237: Fellowes Stor/Drawer Steel Plus Storage Drawers | R2237: 190.86 | S2237: 2 | T2237: 0 | U2237: 11.4516 | V2237: =IF(ISNA(MATCH(Sales!$B2237,Returns!$B$2:$B$297,0)),"No","Yes") -> No | W2237: =INDEX(People!$A$2:$A$5,MATCH(Sales!$M2237,People!$B$2:$B$5,0)) -> Kelly Williams
A2238: 2237 | B2238: CA-2015-145849 | C2238: 42262 | D2238: 42264 | E2238: Second Class | F2238: CT-11995 | G2238: Carol Triggs | H2238: Consumer | I2238: United States | J2238: Indianapolis | K2238: Indiana | L2238: 46203 | M2238: Central | N2238: OFF-AR-10000817 | O2238: Office Supplies | P2238: Art | Q2238: Manco Dry-Lighter Erasable Highlighter | R2238: 24.32 | S2238: 8 | T2238: 0 | U2238: 8.2688 | V2238: =IF(ISNA(MATCH(Sales!$B2238,Returns!$B$2:$B$297,0)),"No","Yes") -> No | W2238: =INDEX(People!$A$2:$A$5,MATCH(Sales!$M2238,People!$B$2:$B$5,0)) -> Kelly Williams
A2239: 2238 | B2239: CA-2016-122322 | C2239: 42566 | D2239: 42572 | E2239: Standard Class | F2239: RH-19510 | G2239: Rick Huthwaite | H2239: Home Office | I2239: United States | J2239: Provo | K2239: Utah | L2239: 84604 | M2239: West | N2239: OFF-SU-10000952 | O2239: Office Supplies | P2239: Supplies | Q2239: Fiskars Home & Office Scissors | R2239: 44.4 | S2239: 5 | T2239: 0 | U2239: 12.432 | V2239: =IF(ISNA(MATCH(Sales!$B2239,Returns!$B$2:$B$297,0)),"No","Yes") -> No | W2239: =INDEX(People!$A$2:$A$5,MATCH(Sales!$M2239,People!$B$2:$B$5,0)) -> Anna Andreadi
A2240: 2239 | B2240: CA-2017-166849 | C2240: 42845 | D2240: 42851 | E2240: Standard Class | F2240: SJ-20125 | G2240: Sanjit Jacobs | H2240: Home Office | I2240: United States | J2240: Chicago | K2240: Illinois | L2240: 60610 | M2240: Central | N2240: FUR-FU-10004597 | O2240: Furniture | P2240: Furnishings | Q2240: Eldon Cleatmat Chair Mats for Medium Pile Carpets | R2240: 44.4 | S2240: 2 | T2240: 0.6 | U2240: -52.17 | V2240: =IF(ISNA(MATCH(Sales!$B2240,Returns!$B$2:$B$297,0)),"No","Yes") -> No | W2240: =INDEX(People!$A$2:$A$5,MATCH(Sales!$M2240,People!$B$2:$B$5,0)) -> Kelly Williams
A2241: 2240 | B2241: CA-2016-146633 | C2241: 42689 | D2241: 42691 | E2241: Second Class | F2241: TG-21310 | G2241: Toby Gnade | H2241: Consumer | I2241: United States | J2241: Los Angeles | K2241: California | L2241: 90049 | M2241: West | N2241: OFF-BI-10003527 | O2241: Office Supplies | P2241: Binders | Q2241: Fellowes PB500 Electric Punch Plastic Comb Binding Machine with Manual Bind | R2241: 1016.792 | S2241: 1 | T2241: 0.2 | U2241: 381.297 | V2241: =IF(ISNA(MATCH(Sales!$B2241,Returns!$B$2:$B$297,0)),"No","Yes") -> No | W2241: =INDEX(People!$A$2:$A$5,MATCH(Sales!$M2241,People!$B$2:$B$5,0)) -> Anna Andreadi
A2242: 2241 | B2242: CA-2016-146633 | C2242: 42689 | D2242: 42691 | E2242: Second Class | F2242: TG-21310 | G2242: Toby Gnade | H2242: Consumer | I2242: United States | J2242: Los Angeles | K2242: California | L2242: 90049 | M2242: West | N2242: OFF-BI-10002982 | O2242: Office Supplies | P2242: Binders | Q2242: Avery Self-Adhesive Photo Pockets for Polaroid Photos | R2242: 38.136 | S2242: 7 | T2242: 0.2 | U2242: 13.3476 | V2242: =IF(ISNA(MATCH(Sales!$B2242,Returns!$B$2:$B$297,0)),"No","Yes") -> No | W2242: =INDEX(People!$A$2:$A$5,MATCH(Sales!$M2242,People!$B$2:$B$5,0)) -> Anna Andreadi
A2243: 2242 | B2243: US-2016-126893 | C2243: 42700 | D2243: 42705 | E2243: Standard Class | F2243: CT-11995 | G2243: Carol Triggs | H2243: Consumer | I2243: United States | J2243: Philadelphia | K2243: Pennsylvania | L2243: 19134 | M2243: East | N2243: TEC-PH-10004165 | O2243: Technology | P2243: Phones | Q2243: Mitel MiVoice 5330e IP Phone | R2243: 494.982 | S2243: 3 | T2243: 0.4 | U2243: -115.4958 | V2243: =IF(ISNA(MATCH(Sales!$B2243,Returns!$B$2:$B$297,0)),"No","Yes") -> No | W2243: =INDEX(People!$A$2:$A$5,MATCH(Sales!$M2243,People!$B$2:$B$5,0)) -> Chuck Magee
A2244: 2243 | B2244: CA-2017-103380 | C2244: 43060 | D2244: 43064 | E2244: Standard Class | F2244: BF-11005 | G2244: Barry Franz | H2244: Home Office | I2244: United States | J2244: Pasadena | K2244: California | L2244: 91104 | M2244: West | N2244: OFF-ST-10003442 | O2244: Office Supplies | P2244: Storage | Q2244: Eldon Portable Mobile Manager | R2244: 56.56 | S2244: 2 | T2244: 0 | U2244: 15.2712 | V2244: =IF(ISNA(MATCH(Sales!$B2244,Returns!$B$2:$B$297,0)),"No","Yes") -> Yes | W2244: =INDEX(People!$A$2:$A$5,MATCH(Sales!$M2244,People!$B$2:$B$5,0)) -> Anna Andreadi
A2245: 2244 | B2245: CA-2017-103380 | C2245: 43060 | D2245: 43064 | E2245: Standard Class | F2245: BF-11005 | G2245: Barry Franz | H2245: Home Office | I2245: United States | J2245: Pasadena | K2245: California | L2245: 91104 | M2245: West | N2245: OFF-AR-10003856 | O2245: Office Supplies | P2245: Art | Q2245: Newell 344 | R2245: 5.56 | S2245: 2 | T2245: 0 | U2245: 1.4456 | V2245: =IF(ISNA(MATCH(Sales!$B2245,Returns!$B$2:$B$297,0)),"No","Yes") -> Yes | W2245: =INDEX(People!$A$2:$A$5,MATCH(Sales!$M2245,People!$B$2:$B$5,0)) -> Anna Andreadi
A2246: 2245 | B2246: CA-2017-103380 | C2246: 43060 | D2246: 43064 | E2246: Standard Class | F2246: BF-11005 | G2246: Barry Franz | H2246: Home Office | I2246: United States | J2246: Pasadena | K2246: California | L2246: 91104 | M2246: West | N2246: OFF-FA-10004248 | O2246: Office Supplies | P2246: Fasteners | Q2246: Advantus T-Pin Paper Clips | R2246: 9.02 | S2246: 2 | T2246: 0 | U2246: 3.5178 | V2246: =IF(ISNA(MATCH(Sales!$B2246,Returns!$B$2:$B$297,0)),"No","Yes") -> Yes | W2246: =INDEX(People!$A$2:$A$5,MATCH(Sales!$M2246,People!$B$2:$B$5,0)) -> Anna Andreadi
A2247: 2246 | B2247: CA-2017-103380 | C2247: 43060 | D2247: 43064 | E2247: Standard Class | F2247: BF-11005 | G2247: Barry Franz | H2247: Home Office | I2247: United States | J2247: Pasadena | K2247: California | L2247: 91104 | M2247: West | N2247: OFF-AP-10001492 | O2247: Office Supplies | P2247: Appliances | Q2247: Acco Six-Outlet Power Strip, 4' Cord Length | R2247: 8.62 | S2247: 1 | T2247: 0 | U2247: 2.2412 | V2247: =IF(ISNA(MATCH(Sales!$B2247,Returns!$B$2:$B$297,0)),"No","Yes") -> Yes | W2247: =INDEX(People!$A$2:$A$5,MATCH(Sales!$M2247,People!$B$2:$B$5,0)) -> Anna Andreadi
A2248: 2247 | B2248: CA-2017-103380 | C2248: 43060 | D2248: 43064 | E2248: Standard Class | F2248: BF-11005 | G2248: Barry Franz | H2248: Home Office | I2248: United States | J2248: Pasadena | K2248: California | L2248: 91104 | M2248: West | N2248: TEC-PH-10004165 | O2248: Technology | P2248: Phones | Q2248: Mitel MiVoice 5330e IP Phone | R2248: 659.976 | S2248: 3 | T2248: 0.2 | U2248: 49.4982 | V2248: =IF(ISNA(MATCH(Sales!$B2248,Returns!$B$2:$B$297,0)),"No","Yes") -> Yes | W2248: =INDEX(People!$A$2:$A$5,MATCH(Sales!$M2248,People!$B$2:$B$5,0)) -> Anna Andreadi
... A5275: 5274 | B5275: US-2016-158309 | C5275: 42700 | D5275: 42703 | E5275: First Class | F5275: PA-19060 | G5275: Pete Armstrong | H5275: Home Office | I5275: United States | J5275: Miami | K5275: Florida | L5275: 33142 | M5275: South | N5275: OFF-BI-10000145 | O5275: Office Supplies | P5275: Binders | Q5275: Zipper Ring Binder Pockets | R5275: 3.744 | S5275: 4 | T5275: 0.7 | U5275: -2.6208 | V5275: =IF(ISNA(MATCH(Sales!$B5275,Returns!$B$2:$B$297,0)),"No","Yes") -> No | W5275: =INDEX(People!$A$2:$A$5,MATCH(Sales!$M5275,People!$B$2:$B$5,0)) -> Cassandra Brandow
A5276: 5275 | B5276: CA-2015-162887 | C5276: 42315 | D5276: 42317 | E5276: Second Class | F5276: SV-20785 | G5276: Stewart Visinsky | H5276: Consumer | I5276: United States | J5276: Burlington | K5276: Vermont | L5276: 05408 | M5276: East | N5276: FUR-CH-10000595 | O5276: Furniture | P5276: Chairs | Q5276: Safco Contoured Stacking Chairs | R5276: 715.2 | S5276: 3 | T5276: 0 | U5276: 178.8 | V5276: =IF(ISNA(MATCH(Sales!$B5276,Returns!$B$2:$B$297,0)),"No","Yes") -> No | W5276: =INDEX(People!$A$2:$A$5,MATCH(Sales!$M5276,People!$B$2:$B$5,0)) -> Chuck Magee
A5277: 5276 | B5277: CA-2017-147333 | C5277: 43083 | D5277: 43089 | E5277: Standard Class | F5277: KL-16555 | G5277: Kelly Lampkin | H5277: Corporate | I5277: United States | J5277: Fayetteville | K5277: Arkansas | L5277: 72701 | M5277: South | N5277: TEC-AC-10004469 | O5277: Technology | P5277: Accessories | Q5277: Microsoft Sculpt Comfort Mouse | R5277: 159.8 | S5277: 4 | T5277: 0 | U5277: 70.312 | V5277: =IF(ISNA(MATCH(Sales!$B5277,Returns!$B$2:$B$297,0)),"No","Yes") -> No | W5277: =INDEX(People!$A$2:$A$5,MATCH(Sales!$M5277,People!$B$2:$B$5,0)) -> Cassandra Brandow
A5278: 5277 | B5278: CA-2017-147333 | C5278: 43083 | D5278: 43089 | E5278: Standard Class | F5278: KL-16555 | G5278: Kelly Lampkin | H5278: Corporate | I5278: United States | J5278: Fayetteville | K5278: Arkansas | L5278: 72701 | M5278: South | N5278: TEC-AC-10003038 | O5278: Technology | P5278: Accessories | Q5278: Kingston Digital DataTraveler 16GB USB 2.0 | R5278: 44.75 | S5278: 5 | T5278: 0 | U5278: 8.5025 | V5278: =IF(ISNA(MATCH(Sales!$B5278,Returns!$B$2:$B$297,0)),"No","Yes") -> No | W5278: =INDEX(People!$A$2:$A$5,MATCH(Sales!$M5278,People!$B$2:$B$5,0)) -> Cassandra Brandow
A5279: 5278 | B5279: CA-2014-113859 | C5279: 41895 | D5279: 41899 | E5279: Standard Class | F5279: BC-11125 | G5279: Becky Castell | H5279: Home Office | I5279: United States | J5279: Odessa | K5279: Texas | L5279: 79762 | M5279: Central | N5279: FUR-CH-10004698 | O5279: Furniture | P5279: Chairs | Q5279: Padded Folding Chairs, Black, 4/Carton | R5279: 340.116 | S5279: 6 | T5279: 0.3 | U5279: -9.7176 | V5279: =IF(ISNA(MATCH(Sales!$B5279,Returns!$B$2:$B$297,0)),"No","Yes") -> No | W5279: =INDEX(People!$A$2:$A$5,MATCH(Sales!$M5279,People!$B$2:$B$5,0)) -> Kelly Williams
A5280: 5279 | B5280: CA-2014-159681 | C5280: 41980 | D5280: 41986 | E5280: Standard Class | F5280: PO-18850 | G5280: Patrick O'Brill | H5280: Consumer | I5280: United States | J5280: Virginia Beach | K5280: Virginia | L5280: 23464 | M5280: South | N5280: OFF-PA-10003641 | O5280: Office Supplies | P5280: Paper | Q5280: Xerox 1909 | R5280: 105.52 | S5280: 4 | T5280: 0 | U5280: 48.5392 | V5280: =IF(ISNA(MATCH(Sales!$B5280,Returns!$B$2:$B$297,0)),"No","Yes") -> No | W5280: =INDEX(People!$A$2:$A$5,MATCH(Sales!$M5280,People!$B$2:$B$5,0)) -> Cassandra Brandow
A5281: 5280 | B5281: US-2017-104094 | C5281: 42985 | D5281: 42989 | E5281: Standard Class | F5281: AG-10675 | G5281: Anna Gayman | H5281: Consumer | I5281: United States | J5281: Milwaukee | K5281: Wisconsin | L5281: 53209 | M5281: Central | N5281: TEC-AC-10002134 | O5281: Technology | P5281: Accessories | Q5281: Rosewill 107 Normal Keys USB Wired Standard Keyboard | R5281: 13.48 | S5281: 1 | T5281: 0 | U5281: 1.8872 | V5281: =IF(ISNA(MATCH(Sales!$B5281,Returns!$B$2:$B$297,0)),"No","Yes") -> No | W5281: =INDEX(People!$A$2:$A$5,MATCH(Sales!$M5281,People!$B$2:$B$5,0)) -> Kelly Williams
A5282: 5281 | B5282: CA-2017-152709 | C5282: 43015 | D5282: 43020 | E5282: Standard Class | F5282: DB-13210 | G5282: Dean Braden | H5282: Consumer | I5282: United States | J5282: Detroit | K5282: Michigan | L5282: 48234 | M5282: Central | N5282: OFF-ST-10001837 | O5282: Office Supplies | P5282: Storage | Q5282: SAFCO Mobile Desk Side File, Wire Frame | R5282: 85.52 | S5282: 2 | T5282: 0 | U5282: 22.2352 | V5282: =IF(ISNA(MATCH(Sales!$B5282,Returns!$B$2:$B$297,0)),"No","Yes") -> No | W5282: =INDEX(People!$A$2:$A$5,MATCH(Sales!$M5282,People!$B$2:$B$5,0)) -> Kelly Williams
A5283: 5282 | B5283: CA-2015-105158 | C5283: 42252 | D5283: 42257 | E5283: Standard Class | F5283: SP-20860 | G5283: Sung Pak | H5283: Corporate | I5283: United States | J5283: Rochester | K5283: Minnesota | L5283: 55901 | M5283: Central | N5283: FUR-FU-10001706 | O5283: Furniture | P5283: Furnishings | Q5283: Longer-Life Soft White Bulbs | R5283: 6.16 | S5283: 2 | T5283: 0 | U5283: 2.9568 | V5283: =IF(ISNA(MATCH(Sales!$B5283,Returns!$B$2:$B$297,0)),"No","Yes") -> Yes | W5283: =INDEX(People!$A$2:$A$5,MATCH(Sales!$M5283,People!$B$2:$B$5,0)) -> Kelly Williams
A5284: 5283 | B5284: CA-2015-105158 | C5284: 42252 | D5284: 42257 | E5284: Standard Class | F5284: SP-20860 | G5284: Sung Pak | H5284: Corporate | I5284: United States | J5284: Rochester | K5284: Minnesota | L5284: 55901 | M5284: Central | N5284: OFF-PA-10001970 | O5284: Office Supplies | P5284: Paper | Q5284: Xerox 1881 | R5284: 36.84 | S5284: 3 | T5284: 0 | U5284: 17.3148 | V5284: =IF(ISNA(MATCH(Sales!$B5284,Returns!$B$2:$B$297,0)),"No","Yes") -> Yes | W5284: =INDEX(People!$A$2:$A$5,MATCH(Sales!$M5284,People!$B$2:$B$5,0)) -> Kelly Williams
...

Sheet Returns
A1: Returned | B1: Order ID
A2: Yes | B2: CA-2017-153822
A3: Yes | B3: CA-2017-129707
A4: Yes | B4: CA-2014-152345
A5: Yes | B5: CA-2015-156440
A6: Yes | B6: US-2017-155999
A7: Yes | B7: CA-2014-157924
A8: Yes | B8: CA-2017-131807
A9: Yes | B9: CA-2016-124527
A10: Yes | B10: CA-2017-135692
A11: Yes | B11: CA-2014-123225
A12: Yes | B12: CA-2017-145772
... A297: Yes | B297: CA-2015-149636

Sheet People
A1: Person | B1: Region
A2: Anna Andreadi | B2: West
A3: Chuck Magee | B3: East
A4: Kelly Williams | B4: Central
A5: Cassandra Brandow | B5: South
